2025-04-06 18:26:49,430 - 16365 - hummingbot.core.utils.async_utils - ERROR - Unhandled error in background task: Non-hexadecimal digit found
Traceback (most recent call last):
  File "/Users/yennefer/Downloads/hummingbot/hummingbot/core/utils/async_utils.py", line 9, in safe_wrapper
    return await c
  File "/Users/yennefer/Downloads/hummingbot/hummingbot/core/utils/async_call_scheduler.py", line 127, in call_async
    return await self.schedule_async_call(coro, timeout_seconds, app_warning_msg=app_warning_msg)
  File "/Users/yennefer/Downloads/hummingbot/hummingbot/core/utils/async_call_scheduler.py", line 116, in schedule_async_call
    return await fut
  File "/Users/yennefer/Downloads/hummingbot/hummingbot/core/utils/async_call_scheduler.py", line 79, in _coro_scheduler
    fut.set_result(await coro)
  File "/Users/yennefer/anaconda3/envs/hummingbot/lib/python3.10/concurrent/futures/thread.py", line 58, in run
    result = self.fn(*self.args, **self.kwargs)
  File "/Users/yennefer/Downloads/hummingbot/hummingbot/client/config/security.py", line 65, in decrypt_all
    cls.decrypt_connector_config(file)
  File "/Users/yennefer/Downloads/hummingbot/hummingbot/client/config/security.py", line 71, in decrypt_connector_config
    cls._secure_configs[connector_name] = load_connector_config_map_from_file(file_path)
  File "/Users/yennefer/Downloads/hummingbot/hummingbot/client/config/config_helpers.py", line 668, in load_connector_config_map_from_file
    _load_yml_data_into_map(config_data, config_map)
  File "/Users/yennefer/Downloads/hummingbot/hummingbot/client/config/config_helpers.py", line 750, in _load_yml_data_into_map
    config_validation_errors = cm.validate_model()  # try coercing values to appropriate type
  File "/Users/yennefer/Downloads/hummingbot/hummingbot/client/config/config_helpers.py", line 199, in validate_model
    self.decrypt_all_secure_data()
  File "/Users/yennefer/Downloads/hummingbot/hummingbot/client/config/config_helpers.py", line 237, in decrypt_all_secure_data
    decrypted_value = Security.secrets_manager.decrypt_secret_value(attr=traversal_item.attr, value=value)
  File "/Users/yennefer/Downloads/hummingbot/hummingbot/client/config/config_crypt.py", line 58, in decrypt_secret_value
    value = binascii.unhexlify(value)
binascii.Error: Non-hexadecimal digit found
2025-04-06 18:26:59,869 - 16365 - hummingbot.connector.time_synchronizer - NETWORK - Error getting server time.
Traceback (most recent call last):
  File "/Users/yennefer/anaconda3/envs/hummingbot/lib/python3.10/site-packages/aiohttp/connector.py", line 1351, in _create_direct_connection
    hosts = await self._resolve_host(host, port, traces=traces)
  File "/Users/yennefer/anaconda3/envs/hummingbot/lib/python3.10/site-packages/aiohttp/connector.py", line 995, in _resolve_host
    return await asyncio.shield(resolved_host_task)
  File "/Users/yennefer/anaconda3/envs/hummingbot/lib/python3.10/site-packages/aiohttp/connector.py", line 1026, in _resolve_host_with_throttle
    addrs = await self._resolver.resolve(host, port, family=self._family)
  File "/Users/yennefer/anaconda3/envs/hummingbot/lib/python3.10/site-packages/aiohttp/resolver.py", line 39, in resolve
    infos = await self._loop.getaddrinfo(
  File "/Users/yennefer/anaconda3/envs/hummingbot/lib/python3.10/asyncio/base_events.py", line 863, in getaddrinfo
    return await self.run_in_executor(
  File "/Users/yennefer/anaconda3/envs/hummingbot/lib/python3.10/concurrent/futures/thread.py", line 58, in run
    result = self.fn(*self.args, **self.kwargs)
  File "/Users/yennefer/anaconda3/envs/hummingbot/lib/python3.10/socket.py", line 967, in getaddrinfo
    for res in _socket.getaddrinfo(host, port, family, type, proto, flags):
socket.gaierror: [Errno 8] nodename nor servname provided, or not known

The above exception was the direct cause of the following exception:

Traceback (most recent call last):
  File "/Users/yennefer/Downloads/hummingbot/hummingbot/connector/time_synchronizer.py", line 66, in update_server_time_offset_with_time_provider
    server_time_ms: float = await time_provider
  File "/Users/yennefer/Downloads/hummingbot/hummingbot/connector/exchange/bybit/bybit_web_utils.py", line 122, in get_current_server_time
    response = await api_request(
  File "/Users/yennefer/Downloads/hummingbot/hummingbot/connector/exchange/bybit/bybit_web_utils.py", line 99, in api_request
    response = await rest_assistant.call(request=request, timeout=timeout)
  File "/Users/yennefer/Downloads/hummingbot/hummingbot/core/web_assistant/rest_assistant.py", line 108, in call
    resp = await wait_for(self._connection.call(request), timeout)
  File "/Users/yennefer/anaconda3/envs/hummingbot/lib/python3.10/asyncio/tasks.py", line 408, in wait_for
    return await fut
  File "/Users/yennefer/Downloads/hummingbot/hummingbot/core/web_assistant/connections/rest_connection.py", line 10, in call
    aiohttp_resp = await self._client_session.request(
  File "/Users/yennefer/anaconda3/envs/hummingbot/lib/python3.10/site-packages/aiohttp/client.py", line 703, in _request
    conn = await self._connector.connect(
  File "/Users/yennefer/anaconda3/envs/hummingbot/lib/python3.10/site-packages/aiohttp/connector.py", line 548, in connect
    proto = await self._create_connection(req, traces, timeout)
  File "/Users/yennefer/anaconda3/envs/hummingbot/lib/python3.10/site-packages/aiohttp/connector.py", line 1056, in _create_connection
    _, proto = await self._create_direct_connection(req, traces, timeout)
  File "/Users/yennefer/anaconda3/envs/hummingbot/lib/python3.10/site-packages/aiohttp/connector.py", line 1357, in _create_direct_connection
    raise ClientConnectorDNSError(req.connection_key, exc) from exc
aiohttp.client_exceptions.ClientConnectorDNSError: Cannot connect to host api-testnet.bybit.com:443 ssl:default [nodename nor servname provided, or not known]
2025-04-06 18:26:59,878 - 16365 - hummingbot.connector.time_synchronizer - WARNING - Could not refresh server time. Check network connection.
2025-04-06 18:26:59,881 - 16365 - hummingbot.connector.time_synchronizer - NETWORK - Error getting server time.
Traceback (most recent call last):
  File "/Users/yennefer/anaconda3/envs/hummingbot/lib/python3.10/site-packages/aiohttp/connector.py", line 1351, in _create_direct_connection
    hosts = await self._resolve_host(host, port, traces=traces)
  File "/Users/yennefer/anaconda3/envs/hummingbot/lib/python3.10/site-packages/aiohttp/connector.py", line 995, in _resolve_host
    return await asyncio.shield(resolved_host_task)
  File "/Users/yennefer/anaconda3/envs/hummingbot/lib/python3.10/site-packages/aiohttp/connector.py", line 1026, in _resolve_host_with_throttle
    addrs = await self._resolver.resolve(host, port, family=self._family)
  File "/Users/yennefer/anaconda3/envs/hummingbot/lib/python3.10/site-packages/aiohttp/resolver.py", line 39, in resolve
    infos = await self._loop.getaddrinfo(
  File "/Users/yennefer/anaconda3/envs/hummingbot/lib/python3.10/asyncio/base_events.py", line 863, in getaddrinfo
    return await self.run_in_executor(
  File "/Users/yennefer/anaconda3/envs/hummingbot/lib/python3.10/concurrent/futures/thread.py", line 58, in run
    result = self.fn(*self.args, **self.kwargs)
  File "/Users/yennefer/anaconda3/envs/hummingbot/lib/python3.10/socket.py", line 967, in getaddrinfo
    for res in _socket.getaddrinfo(host, port, family, type, proto, flags):
socket.gaierror: [Errno 8] nodename nor servname provided, or not known

The above exception was the direct cause of the following exception:

Traceback (most recent call last):
  File "/Users/yennefer/Downloads/hummingbot/hummingbot/connector/time_synchronizer.py", line 66, in update_server_time_offset_with_time_provider
    server_time_ms: float = await time_provider
  File "/Users/yennefer/Downloads/hummingbot/hummingbot/connector/exchange/binance/binance_web_utils.py", line 69, in get_current_server_time
    response = await rest_assistant.execute_request(
  File "/Users/yennefer/Downloads/hummingbot/hummingbot/core/web_assistant/rest_assistant.py", line 47, in execute_request
    response = await self.execute_request_and_get_response(
  File "/Users/yennefer/Downloads/hummingbot/hummingbot/core/web_assistant/rest_assistant.py", line 94, in execute_request_and_get_response
    response = await self.call(request=request, timeout=timeout)
  File "/Users/yennefer/Downloads/hummingbot/hummingbot/core/web_assistant/rest_assistant.py", line 108, in call
    resp = await wait_for(self._connection.call(request), timeout)
  File "/Users/yennefer/anaconda3/envs/hummingbot/lib/python3.10/asyncio/tasks.py", line 408, in wait_for
    return await fut
  File "/Users/yennefer/Downloads/hummingbot/hummingbot/core/web_assistant/connections/rest_connection.py", line 10, in call
    aiohttp_resp = await self._client_session.request(
  File "/Users/yennefer/anaconda3/envs/hummingbot/lib/python3.10/site-packages/aiohttp/client.py", line 703, in _request
    conn = await self._connector.connect(
  File "/Users/yennefer/anaconda3/envs/hummingbot/lib/python3.10/site-packages/aiohttp/connector.py", line 548, in connect
    proto = await self._create_connection(req, traces, timeout)
  File "/Users/yennefer/anaconda3/envs/hummingbot/lib/python3.10/site-packages/aiohttp/connector.py", line 1056, in _create_connection
    _, proto = await self._create_direct_connection(req, traces, timeout)
  File "/Users/yennefer/anaconda3/envs/hummingbot/lib/python3.10/site-packages/aiohttp/connector.py", line 1357, in _create_direct_connection
    raise ClientConnectorDNSError(req.connection_key, exc) from exc
aiohttp.client_exceptions.ClientConnectorDNSError: Cannot connect to host api.binance.com:443 ssl:default [nodename nor servname provided, or not known]
2025-04-06 18:26:59,882 - 16365 - hummingbot.connector.time_synchronizer - WARNING - Could not refresh server time. Check network connection.
2025-04-06 18:26:59,882 - 16365 - hummingbot.connector.time_synchronizer - NETWORK - Error getting server time.
Traceback (most recent call last):
  File "/Users/yennefer/anaconda3/envs/hummingbot/lib/python3.10/site-packages/aiohttp/connector.py", line 1351, in _create_direct_connection
    hosts = await self._resolve_host(host, port, traces=traces)
  File "/Users/yennefer/anaconda3/envs/hummingbot/lib/python3.10/site-packages/aiohttp/connector.py", line 995, in _resolve_host
    return await asyncio.shield(resolved_host_task)
  File "/Users/yennefer/anaconda3/envs/hummingbot/lib/python3.10/site-packages/aiohttp/connector.py", line 1026, in _resolve_host_with_throttle
    addrs = await self._resolver.resolve(host, port, family=self._family)
  File "/Users/yennefer/anaconda3/envs/hummingbot/lib/python3.10/site-packages/aiohttp/resolver.py", line 39, in resolve
    infos = await self._loop.getaddrinfo(
  File "/Users/yennefer/anaconda3/envs/hummingbot/lib/python3.10/asyncio/base_events.py", line 863, in getaddrinfo
    return await self.run_in_executor(
  File "/Users/yennefer/anaconda3/envs/hummingbot/lib/python3.10/concurrent/futures/thread.py", line 58, in run
    result = self.fn(*self.args, **self.kwargs)
  File "/Users/yennefer/anaconda3/envs/hummingbot/lib/python3.10/socket.py", line 967, in getaddrinfo
    for res in _socket.getaddrinfo(host, port, family, type, proto, flags):
socket.gaierror: [Errno 8] nodename nor servname provided, or not known

The above exception was the direct cause of the following exception:

Traceback (most recent call last):
  File "/Users/yennefer/Downloads/hummingbot/hummingbot/connector/time_synchronizer.py", line 66, in update_server_time_offset_with_time_provider
    server_time_ms: float = await time_provider
  File "/Users/yennefer/Downloads/hummingbot/hummingbot/connector/exchange/binance/binance_web_utils.py", line 69, in get_current_server_time
    response = await rest_assistant.execute_request(
  File "/Users/yennefer/Downloads/hummingbot/hummingbot/core/web_assistant/rest_assistant.py", line 47, in execute_request
    response = await self.execute_request_and_get_response(
  File "/Users/yennefer/Downloads/hummingbot/hummingbot/core/web_assistant/rest_assistant.py", line 94, in execute_request_and_get_response
    response = await self.call(request=request, timeout=timeout)
  File "/Users/yennefer/Downloads/hummingbot/hummingbot/core/web_assistant/rest_assistant.py", line 108, in call
    resp = await wait_for(self._connection.call(request), timeout)
  File "/Users/yennefer/anaconda3/envs/hummingbot/lib/python3.10/asyncio/tasks.py", line 408, in wait_for
    return await fut
  File "/Users/yennefer/Downloads/hummingbot/hummingbot/core/web_assistant/connections/rest_connection.py", line 10, in call
    aiohttp_resp = await self._client_session.request(
  File "/Users/yennefer/anaconda3/envs/hummingbot/lib/python3.10/site-packages/aiohttp/client.py", line 703, in _request
    conn = await self._connector.connect(
  File "/Users/yennefer/anaconda3/envs/hummingbot/lib/python3.10/site-packages/aiohttp/connector.py", line 548, in connect
    proto = await self._create_connection(req, traces, timeout)
  File "/Users/yennefer/anaconda3/envs/hummingbot/lib/python3.10/site-packages/aiohttp/connector.py", line 1056, in _create_connection
    _, proto = await self._create_direct_connection(req, traces, timeout)
  File "/Users/yennefer/anaconda3/envs/hummingbot/lib/python3.10/site-packages/aiohttp/connector.py", line 1357, in _create_direct_connection
    raise ClientConnectorDNSError(req.connection_key, exc) from exc
aiohttp.client_exceptions.ClientConnectorDNSError: Cannot connect to host api.binance.com:443 ssl:default [nodename nor servname provided, or not known]
2025-04-06 18:26:59,883 - 16365 - hummingbot.connector.time_synchronizer - WARNING - Could not refresh server time. Check network connection.
2025-04-06 18:26:59,884 - 16365 - hummingbot.connector.time_synchronizer - NETWORK - Error getting server time.
Traceback (most recent call last):
  File "/Users/yennefer/anaconda3/envs/hummingbot/lib/python3.10/site-packages/aiohttp/connector.py", line 1351, in _create_direct_connection
    hosts = await self._resolve_host(host, port, traces=traces)
  File "/Users/yennefer/anaconda3/envs/hummingbot/lib/python3.10/site-packages/aiohttp/connector.py", line 995, in _resolve_host
    return await asyncio.shield(resolved_host_task)
  File "/Users/yennefer/anaconda3/envs/hummingbot/lib/python3.10/site-packages/aiohttp/connector.py", line 1026, in _resolve_host_with_throttle
    addrs = await self._resolver.resolve(host, port, family=self._family)
  File "/Users/yennefer/anaconda3/envs/hummingbot/lib/python3.10/site-packages/aiohttp/resolver.py", line 39, in resolve
    infos = await self._loop.getaddrinfo(
  File "/Users/yennefer/anaconda3/envs/hummingbot/lib/python3.10/asyncio/base_events.py", line 863, in getaddrinfo
    return await self.run_in_executor(
  File "/Users/yennefer/anaconda3/envs/hummingbot/lib/python3.10/concurrent/futures/thread.py", line 58, in run
    result = self.fn(*self.args, **self.kwargs)
  File "/Users/yennefer/anaconda3/envs/hummingbot/lib/python3.10/socket.py", line 967, in getaddrinfo
    for res in _socket.getaddrinfo(host, port, family, type, proto, flags):
socket.gaierror: [Errno 8] nodename nor servname provided, or not known

The above exception was the direct cause of the following exception:

Traceback (most recent call last):
  File "/Users/yennefer/Downloads/hummingbot/hummingbot/connector/time_synchronizer.py", line 66, in update_server_time_offset_with_time_provider
    server_time_ms: float = await time_provider
  File "/Users/yennefer/Downloads/hummingbot/hummingbot/connector/exchange/kucoin/kucoin_web_utils.py", line 74, in get_current_server_time
    response = await rest_assistant.execute_request(
  File "/Users/yennefer/Downloads/hummingbot/hummingbot/core/web_assistant/rest_assistant.py", line 47, in execute_request
    response = await self.execute_request_and_get_response(
  File "/Users/yennefer/Downloads/hummingbot/hummingbot/core/web_assistant/rest_assistant.py", line 94, in execute_request_and_get_response
    response = await self.call(request=request, timeout=timeout)
  File "/Users/yennefer/Downloads/hummingbot/hummingbot/core/web_assistant/rest_assistant.py", line 108, in call
    resp = await wait_for(self._connection.call(request), timeout)
  File "/Users/yennefer/anaconda3/envs/hummingbot/lib/python3.10/asyncio/tasks.py", line 408, in wait_for
    return await fut
  File "/Users/yennefer/Downloads/hummingbot/hummingbot/core/web_assistant/connections/rest_connection.py", line 10, in call
    aiohttp_resp = await self._client_session.request(
  File "/Users/yennefer/anaconda3/envs/hummingbot/lib/python3.10/site-packages/aiohttp/client.py", line 703, in _request
    conn = await self._connector.connect(
  File "/Users/yennefer/anaconda3/envs/hummingbot/lib/python3.10/site-packages/aiohttp/connector.py", line 548, in connect
    proto = await self._create_connection(req, traces, timeout)
  File "/Users/yennefer/anaconda3/envs/hummingbot/lib/python3.10/site-packages/aiohttp/connector.py", line 1056, in _create_connection
    _, proto = await self._create_direct_connection(req, traces, timeout)
  File "/Users/yennefer/anaconda3/envs/hummingbot/lib/python3.10/site-packages/aiohttp/connector.py", line 1357, in _create_direct_connection
    raise ClientConnectorDNSError(req.connection_key, exc) from exc
aiohttp.client_exceptions.ClientConnectorDNSError: Cannot connect to host api.kucoin.com:443 ssl:default [nodename nor servname provided, or not known]
2025-04-06 18:26:59,885 - 16365 - hummingbot.connector.time_synchronizer - WARNING - Could not refresh server time. Check network connection.
2025-04-06 18:26:59,886 - 16365 - hummingbot.connector.exchange.kraken.kraken_exchange.KrakenExchange - ERROR - There was an error requesting exchange info.
Traceback (most recent call last):
  File "/Users/yennefer/anaconda3/envs/hummingbot/lib/python3.10/site-packages/aiohttp/connector.py", line 1351, in _create_direct_connection
    hosts = await self._resolve_host(host, port, traces=traces)
  File "/Users/yennefer/anaconda3/envs/hummingbot/lib/python3.10/site-packages/aiohttp/connector.py", line 995, in _resolve_host
    return await asyncio.shield(resolved_host_task)
  File "/Users/yennefer/anaconda3/envs/hummingbot/lib/python3.10/site-packages/aiohttp/connector.py", line 1026, in _resolve_host_with_throttle
    addrs = await self._resolver.resolve(host, port, family=self._family)
  File "/Users/yennefer/anaconda3/envs/hummingbot/lib/python3.10/site-packages/aiohttp/resolver.py", line 39, in resolve
    infos = await self._loop.getaddrinfo(
  File "/Users/yennefer/anaconda3/envs/hummingbot/lib/python3.10/asyncio/base_events.py", line 863, in getaddrinfo
    return await self.run_in_executor(
  File "/Users/yennefer/anaconda3/envs/hummingbot/lib/python3.10/concurrent/futures/thread.py", line 58, in run
    result = self.fn(*self.args, **self.kwargs)
  File "/Users/yennefer/anaconda3/envs/hummingbot/lib/python3.10/socket.py", line 967, in getaddrinfo
    for res in _socket.getaddrinfo(host, port, family, type, proto, flags):
socket.gaierror: [Errno 8] nodename nor servname provided, or not known

The above exception was the direct cause of the following exception:

Traceback (most recent call last):
  File "/Users/yennefer/Downloads/hummingbot/hummingbot/connector/exchange_py_base.py", line 1073, in _initialize_trading_pair_symbol_map
    exchange_info = await self._make_trading_pairs_request()
  File "/Users/yennefer/Downloads/hummingbot/hummingbot/connector/exchange_py_base.py", line 1086, in _make_trading_pairs_request
    exchange_info = await self._api_get(path_url=self.trading_pairs_request_path)
  File "/Users/yennefer/Downloads/hummingbot/hummingbot/connector/exchange/kraken/kraken_exchange.py", line 190, in _api_get
    return await self._api_request_with_retry(*args, **kwargs)
  File "/Users/yennefer/Downloads/hummingbot/hummingbot/connector/exchange/kraken/kraken_exchange.py", line 353, in _api_request_with_retry
    raise e
  File "/Users/yennefer/Downloads/hummingbot/hummingbot/connector/exchange/kraken/kraken_exchange.py", line 327, in _api_request_with_retry
    response_json = await self._api_request(path_url=path_url, method=method, params=params, data=data,
  File "/Users/yennefer/Downloads/hummingbot/hummingbot/connector/exchange_py_base.py", line 906, in _api_request
    request_result = await rest_assistant.execute_request(
  File "/Users/yennefer/Downloads/hummingbot/hummingbot/core/web_assistant/rest_assistant.py", line 47, in execute_request
    response = await self.execute_request_and_get_response(
  File "/Users/yennefer/Downloads/hummingbot/hummingbot/core/web_assistant/rest_assistant.py", line 94, in execute_request_and_get_response
    response = await self.call(request=request, timeout=timeout)
  File "/Users/yennefer/Downloads/hummingbot/hummingbot/core/web_assistant/rest_assistant.py", line 108, in call
    resp = await wait_for(self._connection.call(request), timeout)
  File "/Users/yennefer/anaconda3/envs/hummingbot/lib/python3.10/asyncio/tasks.py", line 408, in wait_for
    return await fut
  File "/Users/yennefer/Downloads/hummingbot/hummingbot/core/web_assistant/connections/rest_connection.py", line 10, in call
    aiohttp_resp = await self._client_session.request(
  File "/Users/yennefer/anaconda3/envs/hummingbot/lib/python3.10/site-packages/aiohttp/client.py", line 703, in _request
    conn = await self._connector.connect(
  File "/Users/yennefer/anaconda3/envs/hummingbot/lib/python3.10/site-packages/aiohttp/connector.py", line 548, in connect
    proto = await self._create_connection(req, traces, timeout)
  File "/Users/yennefer/anaconda3/envs/hummingbot/lib/python3.10/site-packages/aiohttp/connector.py", line 1056, in _create_connection
    _, proto = await self._create_direct_connection(req, traces, timeout)
  File "/Users/yennefer/anaconda3/envs/hummingbot/lib/python3.10/site-packages/aiohttp/connector.py", line 1357, in _create_direct_connection
    raise ClientConnectorDNSError(req.connection_key, exc) from exc
aiohttp.client_exceptions.ClientConnectorDNSError: Cannot connect to host api.kraken.com:443 ssl:default [nodename nor servname provided, or not known]
2025-04-06 18:26:59,887 - 16365 - hummingbot.connector.time_synchronizer - NETWORK - Error getting server time.
Traceback (most recent call last):
  File "/Users/yennefer/anaconda3/envs/hummingbot/lib/python3.10/site-packages/aiohttp/connector.py", line 1351, in _create_direct_connection
    hosts = await self._resolve_host(host, port, traces=traces)
  File "/Users/yennefer/anaconda3/envs/hummingbot/lib/python3.10/site-packages/aiohttp/connector.py", line 995, in _resolve_host
    return await asyncio.shield(resolved_host_task)
  File "/Users/yennefer/anaconda3/envs/hummingbot/lib/python3.10/site-packages/aiohttp/connector.py", line 1026, in _resolve_host_with_throttle
    addrs = await self._resolver.resolve(host, port, family=self._family)
  File "/Users/yennefer/anaconda3/envs/hummingbot/lib/python3.10/site-packages/aiohttp/resolver.py", line 39, in resolve
    infos = await self._loop.getaddrinfo(
  File "/Users/yennefer/anaconda3/envs/hummingbot/lib/python3.10/asyncio/base_events.py", line 863, in getaddrinfo
    return await self.run_in_executor(
  File "/Users/yennefer/anaconda3/envs/hummingbot/lib/python3.10/concurrent/futures/thread.py", line 58, in run
    result = self.fn(*self.args, **self.kwargs)
  File "/Users/yennefer/anaconda3/envs/hummingbot/lib/python3.10/socket.py", line 967, in getaddrinfo
    for res in _socket.getaddrinfo(host, port, family, type, proto, flags):
socket.gaierror: [Errno 8] nodename nor servname provided, or not known

The above exception was the direct cause of the following exception:

Traceback (most recent call last):
  File "/Users/yennefer/Downloads/hummingbot/hummingbot/connector/time_synchronizer.py", line 66, in update_server_time_offset_with_time_provider
    server_time_ms: float = await time_provider
  File "/Users/yennefer/Downloads/hummingbot/hummingbot/connector/exchange/gate_io/gate_io_web_utils.py", line 67, in get_current_server_time
    response = await rest_assistant.execute_request(
  File "/Users/yennefer/Downloads/hummingbot/hummingbot/core/web_assistant/rest_assistant.py", line 47, in execute_request
    response = await self.execute_request_and_get_response(
  File "/Users/yennefer/Downloads/hummingbot/hummingbot/core/web_assistant/rest_assistant.py", line 94, in execute_request_and_get_response
    response = await self.call(request=request, timeout=timeout)
  File "/Users/yennefer/Downloads/hummingbot/hummingbot/core/web_assistant/rest_assistant.py", line 108, in call
    resp = await wait_for(self._connection.call(request), timeout)
  File "/Users/yennefer/anaconda3/envs/hummingbot/lib/python3.10/asyncio/tasks.py", line 408, in wait_for
    return await fut
  File "/Users/yennefer/Downloads/hummingbot/hummingbot/core/web_assistant/connections/rest_connection.py", line 10, in call
    aiohttp_resp = await self._client_session.request(
  File "/Users/yennefer/anaconda3/envs/hummingbot/lib/python3.10/site-packages/aiohttp/client.py", line 703, in _request
    conn = await self._connector.connect(
  File "/Users/yennefer/anaconda3/envs/hummingbot/lib/python3.10/site-packages/aiohttp/connector.py", line 548, in connect
    proto = await self._create_connection(req, traces, timeout)
  File "/Users/yennefer/anaconda3/envs/hummingbot/lib/python3.10/site-packages/aiohttp/connector.py", line 1056, in _create_connection
    _, proto = await self._create_direct_connection(req, traces, timeout)
  File "/Users/yennefer/anaconda3/envs/hummingbot/lib/python3.10/site-packages/aiohttp/connector.py", line 1357, in _create_direct_connection
    raise ClientConnectorDNSError(req.connection_key, exc) from exc
aiohttp.client_exceptions.ClientConnectorDNSError: Cannot connect to host api.gateio.ws:443 ssl:default [nodename nor servname provided, or not known]
2025-04-06 18:26:59,887 - 16365 - hummingbot.connector.time_synchronizer - WARNING - Could not refresh server time. Check network connection.
2025-04-06 18:28:40,874 - 17206 - hummingbot.core.utils.async_utils - ERROR - Unhandled error in background task: Non-hexadecimal digit found
Traceback (most recent call last):
  File "/Users/yennefer/Downloads/hummingbot/hummingbot/core/utils/async_utils.py", line 9, in safe_wrapper
    return await c
  File "/Users/yennefer/Downloads/hummingbot/hummingbot/core/utils/async_call_scheduler.py", line 127, in call_async
    return await self.schedule_async_call(coro, timeout_seconds, app_warning_msg=app_warning_msg)
  File "/Users/yennefer/Downloads/hummingbot/hummingbot/core/utils/async_call_scheduler.py", line 116, in schedule_async_call
    return await fut
  File "/Users/yennefer/Downloads/hummingbot/hummingbot/core/utils/async_call_scheduler.py", line 79, in _coro_scheduler
    fut.set_result(await coro)
  File "/Users/yennefer/anaconda3/envs/hummingbot/lib/python3.10/concurrent/futures/thread.py", line 58, in run
    result = self.fn(*self.args, **self.kwargs)
  File "/Users/yennefer/Downloads/hummingbot/hummingbot/client/config/security.py", line 65, in decrypt_all
    cls.decrypt_connector_config(file)
  File "/Users/yennefer/Downloads/hummingbot/hummingbot/client/config/security.py", line 71, in decrypt_connector_config
    cls._secure_configs[connector_name] = load_connector_config_map_from_file(file_path)
  File "/Users/yennefer/Downloads/hummingbot/hummingbot/client/config/config_helpers.py", line 668, in load_connector_config_map_from_file
    _load_yml_data_into_map(config_data, config_map)
  File "/Users/yennefer/Downloads/hummingbot/hummingbot/client/config/config_helpers.py", line 750, in _load_yml_data_into_map
    config_validation_errors = cm.validate_model()  # try coercing values to appropriate type
  File "/Users/yennefer/Downloads/hummingbot/hummingbot/client/config/config_helpers.py", line 199, in validate_model
    self.decrypt_all_secure_data()
  File "/Users/yennefer/Downloads/hummingbot/hummingbot/client/config/config_helpers.py", line 237, in decrypt_all_secure_data
    decrypted_value = Security.secrets_manager.decrypt_secret_value(attr=traversal_item.attr, value=value)
  File "/Users/yennefer/Downloads/hummingbot/hummingbot/client/config/config_crypt.py", line 58, in decrypt_secret_value
    value = binascii.unhexlify(value)
binascii.Error: Non-hexadecimal digit found
2025-04-06 18:28:51,201 - 17206 - hummingbot.connector.time_synchronizer - NETWORK - Error getting server time.
Traceback (most recent call last):
  File "/Users/yennefer/anaconda3/envs/hummingbot/lib/python3.10/site-packages/aiohttp/connector.py", line 1351, in _create_direct_connection
    hosts = await self._resolve_host(host, port, traces=traces)
  File "/Users/yennefer/anaconda3/envs/hummingbot/lib/python3.10/site-packages/aiohttp/connector.py", line 995, in _resolve_host
    return await asyncio.shield(resolved_host_task)
  File "/Users/yennefer/anaconda3/envs/hummingbot/lib/python3.10/site-packages/aiohttp/connector.py", line 1026, in _resolve_host_with_throttle
    addrs = await self._resolver.resolve(host, port, family=self._family)
  File "/Users/yennefer/anaconda3/envs/hummingbot/lib/python3.10/site-packages/aiohttp/resolver.py", line 39, in resolve
    infos = await self._loop.getaddrinfo(
  File "/Users/yennefer/anaconda3/envs/hummingbot/lib/python3.10/asyncio/base_events.py", line 863, in getaddrinfo
    return await self.run_in_executor(
  File "/Users/yennefer/anaconda3/envs/hummingbot/lib/python3.10/concurrent/futures/thread.py", line 58, in run
    result = self.fn(*self.args, **self.kwargs)
  File "/Users/yennefer/anaconda3/envs/hummingbot/lib/python3.10/socket.py", line 967, in getaddrinfo
    for res in _socket.getaddrinfo(host, port, family, type, proto, flags):
socket.gaierror: [Errno 8] nodename nor servname provided, or not known

The above exception was the direct cause of the following exception:

Traceback (most recent call last):
  File "/Users/yennefer/Downloads/hummingbot/hummingbot/connector/time_synchronizer.py", line 66, in update_server_time_offset_with_time_provider
    server_time_ms: float = await time_provider
  File "/Users/yennefer/Downloads/hummingbot/hummingbot/connector/exchange/binance/binance_web_utils.py", line 69, in get_current_server_time
    response = await rest_assistant.execute_request(
  File "/Users/yennefer/Downloads/hummingbot/hummingbot/core/web_assistant/rest_assistant.py", line 47, in execute_request
    response = await self.execute_request_and_get_response(
  File "/Users/yennefer/Downloads/hummingbot/hummingbot/core/web_assistant/rest_assistant.py", line 94, in execute_request_and_get_response
    response = await self.call(request=request, timeout=timeout)
  File "/Users/yennefer/Downloads/hummingbot/hummingbot/core/web_assistant/rest_assistant.py", line 108, in call
    resp = await wait_for(self._connection.call(request), timeout)
  File "/Users/yennefer/anaconda3/envs/hummingbot/lib/python3.10/asyncio/tasks.py", line 408, in wait_for
    return await fut
  File "/Users/yennefer/Downloads/hummingbot/hummingbot/core/web_assistant/connections/rest_connection.py", line 10, in call
    aiohttp_resp = await self._client_session.request(
  File "/Users/yennefer/anaconda3/envs/hummingbot/lib/python3.10/site-packages/aiohttp/client.py", line 703, in _request
    conn = await self._connector.connect(
  File "/Users/yennefer/anaconda3/envs/hummingbot/lib/python3.10/site-packages/aiohttp/connector.py", line 548, in connect
    proto = await self._create_connection(req, traces, timeout)
  File "/Users/yennefer/anaconda3/envs/hummingbot/lib/python3.10/site-packages/aiohttp/connector.py", line 1056, in _create_connection
    _, proto = await self._create_direct_connection(req, traces, timeout)
  File "/Users/yennefer/anaconda3/envs/hummingbot/lib/python3.10/site-packages/aiohttp/connector.py", line 1357, in _create_direct_connection
    raise ClientConnectorDNSError(req.connection_key, exc) from exc
aiohttp.client_exceptions.ClientConnectorDNSError: Cannot connect to host api.binance.com:443 ssl:default [nodename nor servname provided, or not known]
2025-04-06 18:28:51,209 - 17206 - hummingbot.connector.time_synchronizer - WARNING - Could not refresh server time. Check network connection.
2025-04-06 18:28:51,210 - 17206 - hummingbot.connector.time_synchronizer - NETWORK - Error getting server time.
Traceback (most recent call last):
  File "/Users/yennefer/anaconda3/envs/hummingbot/lib/python3.10/site-packages/aiohttp/connector.py", line 1351, in _create_direct_connection
    hosts = await self._resolve_host(host, port, traces=traces)
  File "/Users/yennefer/anaconda3/envs/hummingbot/lib/python3.10/site-packages/aiohttp/connector.py", line 995, in _resolve_host
    return await asyncio.shield(resolved_host_task)
  File "/Users/yennefer/anaconda3/envs/hummingbot/lib/python3.10/site-packages/aiohttp/connector.py", line 1026, in _resolve_host_with_throttle
    addrs = await self._resolver.resolve(host, port, family=self._family)
  File "/Users/yennefer/anaconda3/envs/hummingbot/lib/python3.10/site-packages/aiohttp/resolver.py", line 39, in resolve
    infos = await self._loop.getaddrinfo(
  File "/Users/yennefer/anaconda3/envs/hummingbot/lib/python3.10/asyncio/base_events.py", line 863, in getaddrinfo
    return await self.run_in_executor(
  File "/Users/yennefer/anaconda3/envs/hummingbot/lib/python3.10/concurrent/futures/thread.py", line 58, in run
    result = self.fn(*self.args, **self.kwargs)
  File "/Users/yennefer/anaconda3/envs/hummingbot/lib/python3.10/socket.py", line 967, in getaddrinfo
    for res in _socket.getaddrinfo(host, port, family, type, proto, flags):
socket.gaierror: [Errno 8] nodename nor servname provided, or not known

The above exception was the direct cause of the following exception:

Traceback (most recent call last):
  File "/Users/yennefer/Downloads/hummingbot/hummingbot/connector/time_synchronizer.py", line 66, in update_server_time_offset_with_time_provider
    server_time_ms: float = await time_provider
  File "/Users/yennefer/Downloads/hummingbot/hummingbot/connector/exchange/gate_io/gate_io_web_utils.py", line 67, in get_current_server_time
    response = await rest_assistant.execute_request(
  File "/Users/yennefer/Downloads/hummingbot/hummingbot/core/web_assistant/rest_assistant.py", line 47, in execute_request
    response = await self.execute_request_and_get_response(
  File "/Users/yennefer/Downloads/hummingbot/hummingbot/core/web_assistant/rest_assistant.py", line 94, in execute_request_and_get_response
    response = await self.call(request=request, timeout=timeout)
  File "/Users/yennefer/Downloads/hummingbot/hummingbot/core/web_assistant/rest_assistant.py", line 108, in call
    resp = await wait_for(self._connection.call(request), timeout)
  File "/Users/yennefer/anaconda3/envs/hummingbot/lib/python3.10/asyncio/tasks.py", line 408, in wait_for
    return await fut
  File "/Users/yennefer/Downloads/hummingbot/hummingbot/core/web_assistant/connections/rest_connection.py", line 10, in call
    aiohttp_resp = await self._client_session.request(
  File "/Users/yennefer/anaconda3/envs/hummingbot/lib/python3.10/site-packages/aiohttp/client.py", line 703, in _request
    conn = await self._connector.connect(
  File "/Users/yennefer/anaconda3/envs/hummingbot/lib/python3.10/site-packages/aiohttp/connector.py", line 548, in connect
    proto = await self._create_connection(req, traces, timeout)
  File "/Users/yennefer/anaconda3/envs/hummingbot/lib/python3.10/site-packages/aiohttp/connector.py", line 1056, in _create_connection
    _, proto = await self._create_direct_connection(req, traces, timeout)
  File "/Users/yennefer/anaconda3/envs/hummingbot/lib/python3.10/site-packages/aiohttp/connector.py", line 1357, in _create_direct_connection
    raise ClientConnectorDNSError(req.connection_key, exc) from exc
aiohttp.client_exceptions.ClientConnectorDNSError: Cannot connect to host api.gateio.ws:443 ssl:default [nodename nor servname provided, or not known]
2025-04-06 18:28:51,211 - 17206 - hummingbot.connector.time_synchronizer - WARNING - Could not refresh server time. Check network connection.
2025-04-06 18:28:51,211 - 17206 - hummingbot.connector.time_synchronizer - NETWORK - Error getting server time.
Traceback (most recent call last):
  File "/Users/yennefer/anaconda3/envs/hummingbot/lib/python3.10/site-packages/aiohttp/connector.py", line 1351, in _create_direct_connection
    hosts = await self._resolve_host(host, port, traces=traces)
  File "/Users/yennefer/anaconda3/envs/hummingbot/lib/python3.10/site-packages/aiohttp/connector.py", line 995, in _resolve_host
    return await asyncio.shield(resolved_host_task)
  File "/Users/yennefer/anaconda3/envs/hummingbot/lib/python3.10/site-packages/aiohttp/connector.py", line 1026, in _resolve_host_with_throttle
    addrs = await self._resolver.resolve(host, port, family=self._family)
  File "/Users/yennefer/anaconda3/envs/hummingbot/lib/python3.10/site-packages/aiohttp/resolver.py", line 39, in resolve
    infos = await self._loop.getaddrinfo(
  File "/Users/yennefer/anaconda3/envs/hummingbot/lib/python3.10/asyncio/base_events.py", line 863, in getaddrinfo
    return await self.run_in_executor(
  File "/Users/yennefer/anaconda3/envs/hummingbot/lib/python3.10/concurrent/futures/thread.py", line 58, in run
    result = self.fn(*self.args, **self.kwargs)
  File "/Users/yennefer/anaconda3/envs/hummingbot/lib/python3.10/socket.py", line 967, in getaddrinfo
    for res in _socket.getaddrinfo(host, port, family, type, proto, flags):
socket.gaierror: [Errno 8] nodename nor servname provided, or not known

The above exception was the direct cause of the following exception:

Traceback (most recent call last):
  File "/Users/yennefer/Downloads/hummingbot/hummingbot/connector/time_synchronizer.py", line 66, in update_server_time_offset_with_time_provider
    server_time_ms: float = await time_provider
  File "/Users/yennefer/Downloads/hummingbot/hummingbot/connector/exchange/kucoin/kucoin_web_utils.py", line 74, in get_current_server_time
    response = await rest_assistant.execute_request(
  File "/Users/yennefer/Downloads/hummingbot/hummingbot/core/web_assistant/rest_assistant.py", line 47, in execute_request
    response = await self.execute_request_and_get_response(
  File "/Users/yennefer/Downloads/hummingbot/hummingbot/core/web_assistant/rest_assistant.py", line 94, in execute_request_and_get_response
    response = await self.call(request=request, timeout=timeout)
  File "/Users/yennefer/Downloads/hummingbot/hummingbot/core/web_assistant/rest_assistant.py", line 108, in call
    resp = await wait_for(self._connection.call(request), timeout)
  File "/Users/yennefer/anaconda3/envs/hummingbot/lib/python3.10/asyncio/tasks.py", line 408, in wait_for
    return await fut
  File "/Users/yennefer/Downloads/hummingbot/hummingbot/core/web_assistant/connections/rest_connection.py", line 10, in call
    aiohttp_resp = await self._client_session.request(
  File "/Users/yennefer/anaconda3/envs/hummingbot/lib/python3.10/site-packages/aiohttp/client.py", line 703, in _request
    conn = await self._connector.connect(
  File "/Users/yennefer/anaconda3/envs/hummingbot/lib/python3.10/site-packages/aiohttp/connector.py", line 548, in connect
    proto = await self._create_connection(req, traces, timeout)
  File "/Users/yennefer/anaconda3/envs/hummingbot/lib/python3.10/site-packages/aiohttp/connector.py", line 1056, in _create_connection
    _, proto = await self._create_direct_connection(req, traces, timeout)
  File "/Users/yennefer/anaconda3/envs/hummingbot/lib/python3.10/site-packages/aiohttp/connector.py", line 1357, in _create_direct_connection
    raise ClientConnectorDNSError(req.connection_key, exc) from exc
aiohttp.client_exceptions.ClientConnectorDNSError: Cannot connect to host api.kucoin.com:443 ssl:default [nodename nor servname provided, or not known]
2025-04-06 18:28:51,212 - 17206 - hummingbot.connector.time_synchronizer - WARNING - Could not refresh server time. Check network connection.
2025-04-06 18:28:51,212 - 17206 - hummingbot.connector.time_synchronizer - NETWORK - Error getting server time.
Traceback (most recent call last):
  File "/Users/yennefer/anaconda3/envs/hummingbot/lib/python3.10/site-packages/aiohttp/connector.py", line 1351, in _create_direct_connection
    hosts = await self._resolve_host(host, port, traces=traces)
  File "/Users/yennefer/anaconda3/envs/hummingbot/lib/python3.10/site-packages/aiohttp/connector.py", line 995, in _resolve_host
    return await asyncio.shield(resolved_host_task)
  File "/Users/yennefer/anaconda3/envs/hummingbot/lib/python3.10/site-packages/aiohttp/connector.py", line 1026, in _resolve_host_with_throttle
    addrs = await self._resolver.resolve(host, port, family=self._family)
  File "/Users/yennefer/anaconda3/envs/hummingbot/lib/python3.10/site-packages/aiohttp/resolver.py", line 39, in resolve
    infos = await self._loop.getaddrinfo(
  File "/Users/yennefer/anaconda3/envs/hummingbot/lib/python3.10/asyncio/base_events.py", line 863, in getaddrinfo
    return await self.run_in_executor(
  File "/Users/yennefer/anaconda3/envs/hummingbot/lib/python3.10/concurrent/futures/thread.py", line 58, in run
    result = self.fn(*self.args, **self.kwargs)
  File "/Users/yennefer/anaconda3/envs/hummingbot/lib/python3.10/socket.py", line 967, in getaddrinfo
    for res in _socket.getaddrinfo(host, port, family, type, proto, flags):
socket.gaierror: [Errno 8] nodename nor servname provided, or not known

The above exception was the direct cause of the following exception:

Traceback (most recent call last):
  File "/Users/yennefer/Downloads/hummingbot/hummingbot/connector/time_synchronizer.py", line 66, in update_server_time_offset_with_time_provider
    server_time_ms: float = await time_provider
  File "/Users/yennefer/Downloads/hummingbot/hummingbot/connector/exchange/binance/binance_web_utils.py", line 69, in get_current_server_time
    response = await rest_assistant.execute_request(
  File "/Users/yennefer/Downloads/hummingbot/hummingbot/core/web_assistant/rest_assistant.py", line 47, in execute_request
    response = await self.execute_request_and_get_response(
  File "/Users/yennefer/Downloads/hummingbot/hummingbot/core/web_assistant/rest_assistant.py", line 94, in execute_request_and_get_response
    response = await self.call(request=request, timeout=timeout)
  File "/Users/yennefer/Downloads/hummingbot/hummingbot/core/web_assistant/rest_assistant.py", line 108, in call
    resp = await wait_for(self._connection.call(request), timeout)
  File "/Users/yennefer/anaconda3/envs/hummingbot/lib/python3.10/asyncio/tasks.py", line 408, in wait_for
    return await fut
  File "/Users/yennefer/Downloads/hummingbot/hummingbot/core/web_assistant/connections/rest_connection.py", line 10, in call
    aiohttp_resp = await self._client_session.request(
  File "/Users/yennefer/anaconda3/envs/hummingbot/lib/python3.10/site-packages/aiohttp/client.py", line 703, in _request
    conn = await self._connector.connect(
  File "/Users/yennefer/anaconda3/envs/hummingbot/lib/python3.10/site-packages/aiohttp/connector.py", line 548, in connect
    proto = await self._create_connection(req, traces, timeout)
  File "/Users/yennefer/anaconda3/envs/hummingbot/lib/python3.10/site-packages/aiohttp/connector.py", line 1056, in _create_connection
    _, proto = await self._create_direct_connection(req, traces, timeout)
  File "/Users/yennefer/anaconda3/envs/hummingbot/lib/python3.10/site-packages/aiohttp/connector.py", line 1357, in _create_direct_connection
    raise ClientConnectorDNSError(req.connection_key, exc) from exc
aiohttp.client_exceptions.ClientConnectorDNSError: Cannot connect to host api.binance.com:443 ssl:default [nodename nor servname provided, or not known]
2025-04-06 18:28:51,213 - 17206 - hummingbot.connector.time_synchronizer - WARNING - Could not refresh server time. Check network connection.
2025-04-06 18:28:51,214 - 17206 - hummingbot.connector.exchange.kraken.kraken_exchange.KrakenExchange - ERROR - There was an error requesting exchange info.
Traceback (most recent call last):
  File "/Users/yennefer/anaconda3/envs/hummingbot/lib/python3.10/site-packages/aiohttp/connector.py", line 1351, in _create_direct_connection
    hosts = await self._resolve_host(host, port, traces=traces)
  File "/Users/yennefer/anaconda3/envs/hummingbot/lib/python3.10/site-packages/aiohttp/connector.py", line 995, in _resolve_host
    return await asyncio.shield(resolved_host_task)
  File "/Users/yennefer/anaconda3/envs/hummingbot/lib/python3.10/site-packages/aiohttp/connector.py", line 1026, in _resolve_host_with_throttle
    addrs = await self._resolver.resolve(host, port, family=self._family)
  File "/Users/yennefer/anaconda3/envs/hummingbot/lib/python3.10/site-packages/aiohttp/resolver.py", line 39, in resolve
    infos = await self._loop.getaddrinfo(
  File "/Users/yennefer/anaconda3/envs/hummingbot/lib/python3.10/asyncio/base_events.py", line 863, in getaddrinfo
    return await self.run_in_executor(
  File "/Users/yennefer/anaconda3/envs/hummingbot/lib/python3.10/concurrent/futures/thread.py", line 58, in run
    result = self.fn(*self.args, **self.kwargs)
  File "/Users/yennefer/anaconda3/envs/hummingbot/lib/python3.10/socket.py", line 967, in getaddrinfo
    for res in _socket.getaddrinfo(host, port, family, type, proto, flags):
socket.gaierror: [Errno 8] nodename nor servname provided, or not known

The above exception was the direct cause of the following exception:

Traceback (most recent call last):
  File "/Users/yennefer/Downloads/hummingbot/hummingbot/connector/exchange_py_base.py", line 1073, in _initialize_trading_pair_symbol_map
    exchange_info = await self._make_trading_pairs_request()
  File "/Users/yennefer/Downloads/hummingbot/hummingbot/connector/exchange_py_base.py", line 1086, in _make_trading_pairs_request
    exchange_info = await self._api_get(path_url=self.trading_pairs_request_path)
  File "/Users/yennefer/Downloads/hummingbot/hummingbot/connector/exchange/kraken/kraken_exchange.py", line 190, in _api_get
    return await self._api_request_with_retry(*args, **kwargs)
  File "/Users/yennefer/Downloads/hummingbot/hummingbot/connector/exchange/kraken/kraken_exchange.py", line 353, in _api_request_with_retry
    raise e
  File "/Users/yennefer/Downloads/hummingbot/hummingbot/connector/exchange/kraken/kraken_exchange.py", line 327, in _api_request_with_retry
    response_json = await self._api_request(path_url=path_url, method=method, params=params, data=data,
  File "/Users/yennefer/Downloads/hummingbot/hummingbot/connector/exchange_py_base.py", line 906, in _api_request
    request_result = await rest_assistant.execute_request(
  File "/Users/yennefer/Downloads/hummingbot/hummingbot/core/web_assistant/rest_assistant.py", line 47, in execute_request
    response = await self.execute_request_and_get_response(
  File "/Users/yennefer/Downloads/hummingbot/hummingbot/core/web_assistant/rest_assistant.py", line 94, in execute_request_and_get_response
    response = await self.call(request=request, timeout=timeout)
  File "/Users/yennefer/Downloads/hummingbot/hummingbot/core/web_assistant/rest_assistant.py", line 108, in call
    resp = await wait_for(self._connection.call(request), timeout)
  File "/Users/yennefer/anaconda3/envs/hummingbot/lib/python3.10/asyncio/tasks.py", line 408, in wait_for
    return await fut
  File "/Users/yennefer/Downloads/hummingbot/hummingbot/core/web_assistant/connections/rest_connection.py", line 10, in call
    aiohttp_resp = await self._client_session.request(
  File "/Users/yennefer/anaconda3/envs/hummingbot/lib/python3.10/site-packages/aiohttp/client.py", line 703, in _request
    conn = await self._connector.connect(
  File "/Users/yennefer/anaconda3/envs/hummingbot/lib/python3.10/site-packages/aiohttp/connector.py", line 548, in connect
    proto = await self._create_connection(req, traces, timeout)
  File "/Users/yennefer/anaconda3/envs/hummingbot/lib/python3.10/site-packages/aiohttp/connector.py", line 1056, in _create_connection
    _, proto = await self._create_direct_connection(req, traces, timeout)
  File "/Users/yennefer/anaconda3/envs/hummingbot/lib/python3.10/site-packages/aiohttp/connector.py", line 1357, in _create_direct_connection
    raise ClientConnectorDNSError(req.connection_key, exc) from exc
aiohttp.client_exceptions.ClientConnectorDNSError: Cannot connect to host api.kraken.com:443 ssl:default [nodename nor servname provided, or not known]
2025-04-06 18:28:51,216 - 17206 - hummingbot.connector.time_synchronizer - NETWORK - Error getting server time.
Traceback (most recent call last):
  File "/Users/yennefer/anaconda3/envs/hummingbot/lib/python3.10/site-packages/aiohttp/connector.py", line 1351, in _create_direct_connection
    hosts = await self._resolve_host(host, port, traces=traces)
  File "/Users/yennefer/anaconda3/envs/hummingbot/lib/python3.10/site-packages/aiohttp/connector.py", line 995, in _resolve_host
    return await asyncio.shield(resolved_host_task)
  File "/Users/yennefer/anaconda3/envs/hummingbot/lib/python3.10/site-packages/aiohttp/connector.py", line 1026, in _resolve_host_with_throttle
    addrs = await self._resolver.resolve(host, port, family=self._family)
  File "/Users/yennefer/anaconda3/envs/hummingbot/lib/python3.10/site-packages/aiohttp/resolver.py", line 39, in resolve
    infos = await self._loop.getaddrinfo(
  File "/Users/yennefer/anaconda3/envs/hummingbot/lib/python3.10/asyncio/base_events.py", line 863, in getaddrinfo
    return await self.run_in_executor(
  File "/Users/yennefer/anaconda3/envs/hummingbot/lib/python3.10/concurrent/futures/thread.py", line 58, in run
    result = self.fn(*self.args, **self.kwargs)
  File "/Users/yennefer/anaconda3/envs/hummingbot/lib/python3.10/socket.py", line 967, in getaddrinfo
    for res in _socket.getaddrinfo(host, port, family, type, proto, flags):
socket.gaierror: [Errno 8] nodename nor servname provided, or not known

The above exception was the direct cause of the following exception:

Traceback (most recent call last):
  File "/Users/yennefer/Downloads/hummingbot/hummingbot/connector/time_synchronizer.py", line 66, in update_server_time_offset_with_time_provider
    server_time_ms: float = await time_provider
  File "/Users/yennefer/Downloads/hummingbot/hummingbot/connector/exchange/bybit/bybit_web_utils.py", line 122, in get_current_server_time
    response = await api_request(
  File "/Users/yennefer/Downloads/hummingbot/hummingbot/connector/exchange/bybit/bybit_web_utils.py", line 99, in api_request
    response = await rest_assistant.call(request=request, timeout=timeout)
  File "/Users/yennefer/Downloads/hummingbot/hummingbot/core/web_assistant/rest_assistant.py", line 108, in call
    resp = await wait_for(self._connection.call(request), timeout)
  File "/Users/yennefer/anaconda3/envs/hummingbot/lib/python3.10/asyncio/tasks.py", line 408, in wait_for
    return await fut
  File "/Users/yennefer/Downloads/hummingbot/hummingbot/core/web_assistant/connections/rest_connection.py", line 10, in call
    aiohttp_resp = await self._client_session.request(
  File "/Users/yennefer/anaconda3/envs/hummingbot/lib/python3.10/site-packages/aiohttp/client.py", line 703, in _request
    conn = await self._connector.connect(
  File "/Users/yennefer/anaconda3/envs/hummingbot/lib/python3.10/site-packages/aiohttp/connector.py", line 548, in connect
    proto = await self._create_connection(req, traces, timeout)
  File "/Users/yennefer/anaconda3/envs/hummingbot/lib/python3.10/site-packages/aiohttp/connector.py", line 1056, in _create_connection
    _, proto = await self._create_direct_connection(req, traces, timeout)
  File "/Users/yennefer/anaconda3/envs/hummingbot/lib/python3.10/site-packages/aiohttp/connector.py", line 1357, in _create_direct_connection
    raise ClientConnectorDNSError(req.connection_key, exc) from exc
aiohttp.client_exceptions.ClientConnectorDNSError: Cannot connect to host api-testnet.bybit.com:443 ssl:default [nodename nor servname provided, or not known]
2025-04-06 18:28:51,216 - 17206 - hummingbot.connector.time_synchronizer - WARNING - Could not refresh server time. Check network connection.
2025-04-06 18:31:46,465 - 17675 - hummingbot.core.utils.async_utils - ERROR - Unhandled error in background task: Non-hexadecimal digit found
Traceback (most recent call last):
  File "/Users/yennefer/Downloads/hummingbot/hummingbot/core/utils/async_utils.py", line 9, in safe_wrapper
    return await c
  File "/Users/yennefer/Downloads/hummingbot/hummingbot/core/utils/async_call_scheduler.py", line 127, in call_async
    return await self.schedule_async_call(coro, timeout_seconds, app_warning_msg=app_warning_msg)
  File "/Users/yennefer/Downloads/hummingbot/hummingbot/core/utils/async_call_scheduler.py", line 116, in schedule_async_call
    return await fut
  File "/Users/yennefer/Downloads/hummingbot/hummingbot/core/utils/async_call_scheduler.py", line 79, in _coro_scheduler
    fut.set_result(await coro)
  File "/Users/yennefer/anaconda3/envs/hummingbot/lib/python3.10/concurrent/futures/thread.py", line 58, in run
    result = self.fn(*self.args, **self.kwargs)
  File "/Users/yennefer/Downloads/hummingbot/hummingbot/client/config/security.py", line 65, in decrypt_all
    cls.decrypt_connector_config(file)
  File "/Users/yennefer/Downloads/hummingbot/hummingbot/client/config/security.py", line 71, in decrypt_connector_config
    cls._secure_configs[connector_name] = load_connector_config_map_from_file(file_path)
  File "/Users/yennefer/Downloads/hummingbot/hummingbot/client/config/config_helpers.py", line 668, in load_connector_config_map_from_file
    _load_yml_data_into_map(config_data, config_map)
  File "/Users/yennefer/Downloads/hummingbot/hummingbot/client/config/config_helpers.py", line 750, in _load_yml_data_into_map
    config_validation_errors = cm.validate_model()  # try coercing values to appropriate type
  File "/Users/yennefer/Downloads/hummingbot/hummingbot/client/config/config_helpers.py", line 199, in validate_model
    self.decrypt_all_secure_data()
  File "/Users/yennefer/Downloads/hummingbot/hummingbot/client/config/config_helpers.py", line 237, in decrypt_all_secure_data
    decrypted_value = Security.secrets_manager.decrypt_secret_value(attr=traversal_item.attr, value=value)
  File "/Users/yennefer/Downloads/hummingbot/hummingbot/client/config/config_crypt.py", line 58, in decrypt_secret_value
    value = binascii.unhexlify(value)
binascii.Error: Non-hexadecimal digit found
2025-04-06 18:32:29,871 - 17824 - hummingbot.core.utils.async_utils - ERROR - Unhandled error in background task: Non-hexadecimal digit found
Traceback (most recent call last):
  File "/Users/yennefer/Downloads/hummingbot/hummingbot/core/utils/async_utils.py", line 9, in safe_wrapper
    return await c
  File "/Users/yennefer/Downloads/hummingbot/hummingbot/core/utils/async_call_scheduler.py", line 127, in call_async
    return await self.schedule_async_call(coro, timeout_seconds, app_warning_msg=app_warning_msg)
  File "/Users/yennefer/Downloads/hummingbot/hummingbot/core/utils/async_call_scheduler.py", line 116, in schedule_async_call
    return await fut
  File "/Users/yennefer/Downloads/hummingbot/hummingbot/core/utils/async_call_scheduler.py", line 79, in _coro_scheduler
    fut.set_result(await coro)
  File "/Users/yennefer/anaconda3/envs/hummingbot/lib/python3.10/concurrent/futures/thread.py", line 58, in run
    result = self.fn(*self.args, **self.kwargs)
  File "/Users/yennefer/Downloads/hummingbot/hummingbot/client/config/security.py", line 65, in decrypt_all
    cls.decrypt_connector_config(file)
  File "/Users/yennefer/Downloads/hummingbot/hummingbot/client/config/security.py", line 71, in decrypt_connector_config
    cls._secure_configs[connector_name] = load_connector_config_map_from_file(file_path)
  File "/Users/yennefer/Downloads/hummingbot/hummingbot/client/config/config_helpers.py", line 668, in load_connector_config_map_from_file
    _load_yml_data_into_map(config_data, config_map)
  File "/Users/yennefer/Downloads/hummingbot/hummingbot/client/config/config_helpers.py", line 750, in _load_yml_data_into_map
    config_validation_errors = cm.validate_model()  # try coercing values to appropriate type
  File "/Users/yennefer/Downloads/hummingbot/hummingbot/client/config/config_helpers.py", line 199, in validate_model
    self.decrypt_all_secure_data()
  File "/Users/yennefer/Downloads/hummingbot/hummingbot/client/config/config_helpers.py", line 237, in decrypt_all_secure_data
    decrypted_value = Security.secrets_manager.decrypt_secret_value(attr=traversal_item.attr, value=value)
  File "/Users/yennefer/Downloads/hummingbot/hummingbot/client/config/config_crypt.py", line 58, in decrypt_secret_value
    value = binascii.unhexlify(value)
binascii.Error: Non-hexadecimal digit found
